Workbook

Sheet DeadStockInventory
A1: SKU | B1: Product_Name | C1: Category | D1: Supplier | E1: Warehouse | F1: Quantity_On_Hand | G1: Cost_Price_PKR | H1: Selling_Price_PKR | I1: Last_Sale_Date | J1: Units_Sold_Last_90Days | K1: Avg_Daily_Sales | L1: Lead_Time_Days | M1: Safety_Stock_Units | N1: Reorder_Point | O1: Last_Restock_Date
A2: SKU-5035 | B2: Electric Kettle 1.7L | C2: Home & Kitchen | D2: FashionHub Karachi | E2: Lahore Distribution Hub | F2: 125 | G2: 11240.84 | H2: 21532.76 | I2: 45673 | J2: 27 | K2: 6.15 | L2: 19 | M2: 21 | N2: 138 | O2: 45601
A3: SKU-5050 | B3: Multivitamin 60 Tabs | C3: Health & Beauty | D3: GammaSources Karachi | E3: Karachi North Depot | F3: 266 | G3: 13724.92 | H3: 10571.67 | J3: 98 | K3: 6.61 | L3: 17 | M3: 37 | N3: 149 | O3: 45733
A4: SKU-5057 | B4: Nail Kit Manicure | C4: Health & Beauty | D4: TechWorld Pvt Ltd | E4: Islamabad Storage | F4: 108 | G4: 5279.72 | H4: 6714.94 | I4: 45745 | J4: 90 | K4: 3.58 | L4: 32 | M4: 11 | N4: 126 | O4: 45577
A5: SKU-5070 | B5: Tennis Ball Pack 3 | C5: Sports & Outdoor | D5: GammaSources Karachi | E5: Karachi Central Warehouse | F5: 316 | G5: 13131.29 | H5: 29242.82 | I5: 45661 | J5: 3 | K5: 6.79 | L5: 6 | M5: 35 | N5: 76 | O5: 45300
A6: SKU-5024 | B6: Zip Hoodie | C6: Clothing | D6: MedPlus Distributors | E6: Islamabad Storage | F6: 119 | G6: 3337.44 | H6: 5226.38 | I6: 45766 | J6: 44 | K6: 3.52 | L6: 28 | M6: 25 | N6: 124 | O6: 45738
A7: SKU-5025 | B7: Socks 6-pack | C7: Clothing | D7: SportZone Pakistan | E7: Karachi North Depot | F7: 209 | G7: 9430.58 | H7: 21444.38 | I7: 45774 | J7: 8 | K7: 5 | L7: 35 | M7: 26 | N7: 201 | O7: 45593
A8: SKU-5014 | B8: Dash Cam | C8: Electronics | D8: GammaSources Karachi | E8: Lahore Distribution Hub | F8: 10 | G8: 15584.01 | H8: 21764.48 | I8: 45738 | J8: 33 | K8: 2.32 | L8: 34 | M8: 34 | N8: 113 | O8: 45663
A9: SKU-5055 | B9: Face Wash Neem | C9: Health & Beauty | D9: HomeEssentials Co. | E9: Karachi North Depot | F9: 522 | G9: 17657.6 | H9: 20874.69 | I9: 45754 | J9: 42 | K9: 7 | L9: 32 | M9: 11 | N9: 235 | O9: 45315
A10: SKU-5037 | B10: Rice Cooker 1.8L | C10: Home & Kitchen | D10: GammaSources Karachi | E10: Lahore Distribution Hub | F10: 78 | G10: 883.08 | H10: 1970.47 | I10: 45749 | J10: 43 | K10: 6.59 | L10: 5 | M10: 31 | N10: 64 | O10: 45538
A11: SKU-5045 | B11: Face Moisturizer SPF30 | C11: Health & Beauty | D11: HomeEssentials Co. | E11: Karachi Central Warehouse | F11: 109 | G11: 5601.04 | H11: 12009.64 | I11: 45761 | J11: 26 | K11: 2.15 | L11: 25 | M11: 18 | N11: 72 | O11: 45551
A12: SKU-5067 | B12: Badminton Racket Set | C12: Sports & Outdoor | D12: MedPlus Distributors | E12: Karachi Central Warehouse | F12: 101 | G12: 17432.49 | H12: 43662.13 | I12: 45708 | J12: 82 | K12: 0.45 | L12: 25 | M12: 6 | N12: 17 | O12: 45336
A13: SKU-5004 | B13: Power Bank 20000mAh | C13: Electronics | D13: SportZone Pakistan | E13: Karachi Central Warehouse | F13: 578 | G13: 8401.34 | H13: 22470.7 | J13: 41 | K13: 1.87 | L13: 31 | M13: 8 | N13: 66 | O13: 45652
A14: SKU-5002 | B14: USB-C Hub | C14: Electronics | D14: MedPlus Distributors | E14: Karachi Central Warehouse | F14: 557 | G14: 10926.51 | H14: 25633.04 | I14: 45703 | J14: 118 | K14: 4.44 | L14: 17 | M14: 10 | N14: 85 | O14: 45737
A15: SKU-5059 | B15: Collagen Supplement | C15: Health & Beauty | D15: GammaSources Karachi | E15: Islamabad Storage | F15: 567 | G15: 16195.52 | H15: 25965 | I15: 45714 | J15: 56 | K15: 7.9 | L15: 35 | M15: 27 | N15: 304 | O15: 45659
A16: SKU-5030 | B16: Pressure Cooker 5L | C16: Home & Kitchen | D16: AlphaSupplies Lahore | E16: Karachi Central Warehouse | F16: 291 | G16: 8183.75 | H16: 20712.82 | I16: 45440 | J16: 66 | K16: 2.23 | L16: 20 | M16: 20 | N16: 65 | O16: 45690
A18: SKU-5006 | B18: Webcam HD 1080p | C18: Electronics | D18: SportZone Pakistan | E18: Karachi Central Warehouse | F18: 120 | G18: 9245.04 | H18: 11086.24 | I18: 45613 | J18: 20 | K18: 4.79 | L18: 30 | M18: 32 | N18: 176 | O18: 45412
A20: SKU-5060 | B20: Yoga Mat 6mm | C20: Sports & Outdoor | D20: TechWorld Pvt Ltd | E20: Karachi North Depot | F20: 596 | G20: 8775.26 | H20: 18259.83 | I20: 45747 | J20: 89 | K20: 7.82 | L20: 14 | M20: 6 | N20: 115 | O20: 45334
A21: SKU-5012 | B21: Router WiFi 6 | C21: Electronics | D21: AlphaSupplies Lahore | E21: Karachi Central Warehouse | F21: 441 | G21: 3548.82 | H21: 6544.61 | I21: 45731 | J21: 110 | K21: 5.4 | L21: 28 | M21: 8 | N21: 159 | O21: 45633
A22: SKU-5033 | B22: Water Filter Jug | C22: Home & Kitchen | D22: MedPlus Distributors | E22: Karachi North Depot | F22: 585 | G22: 17655.89 | H22: 46675.83 | I22: 45740 | J22: 10 | K22: 1.13 | L22: 25 | M22: 32 | N22: 60 | O22: 45593
A23: SKU-5001 | B23: Bluetooth Speaker | C23: Electronics | D23: FashionHub Karachi | E23: Karachi North Depot | F23: 14 | G23: 7638.43 | H23: 12124.94 | I23: 45404 | J23: 20 | K23: 2.75 | L23: 27 | M23: 32 | N23: 106 | O23: 45711
A24: SKU-5029 | B24: Thermal Underwear | C24: Clothing | D24: BetaTraders Islamabad | E24: Karachi North Depot | F24: 132 | G24: 8442.22 | H24: 22467.7 | I24: 45418 | J24: 102 | K24: 7.9 | L24: 19 | M24: 38 | N24: 188 | O24: 45301
A25: SKU-5040 | B25: Knife Set 5pc | C25: Home & Kitchen | D25: GammaSources Karachi | E25: Islamabad Storage | F25: 510 | G25: 8871.11 | H25: 20228.12 | I25: 45475 | J25: 2 | K25: 1.81 | L25: 7 | M25: 23 | N25: 36 | O25: 45543
A26: SKU-5016 | B26: Women Kurta Embroidered | C26: Clothing | D26: AlphaSupplies Lahore | E26: Lahore Distribution Hub | F26: 600 | G26: 7357.39 | H26: 15281.7 | I26: 45563 | J26: 79 | K26: 5.28 | L26: 7 | M26: 31 | N26: 68 | O26: 45625
A27: SKU-5015 | B27: Men Polo Shirt | C27: Clothing | D27: HomeEssentials Co. | E27: Karachi Central Warehouse | F27: 329 | G27: 1193.93 | H27: 1459.47 | I27: 45684 | J27: 74 | K27: 7.36 | L27: 20 | M27: 37 | N27: 184 | O27: 45456
... A33: SKU-5041 | B33: Food Storage Containers | C33: Home & Kitchen | D33: MedPlus Distributors | E33: Karachi North Depot | F33: 265 | G33: 6054.62 | H33: 9536.87 | I33: 45757 | J33: 92 | K33: 1 | L33: 11 | M33: 25 | N33: 36 | O33: 45619
A34: SKU-5022 | B34: Formal Trousers | C34: Clothing | D34: MedPlus Distributors | E34: Karachi North Depot | F34: 262 | G34: 16765.06 | H34: 43113.49 | J34: 100 | K34: 3.09 | L34: 27 | M34: 11 | N34: 94 | O34: 45581
A35: SKU-5007 | B35: Gaming Mouse | C35: Electronics | D35: HomeEssentials Co. | E35: Karachi Central Warehouse | F35: 356 | G35: 15943.47 | H35: 38443.63 | I35: 45753 | J35: 55 | K35: 0.08 | L35: 10 | M35: 34 | N35: 35 | O35: 45315
A36: SKU-5032 | B36: Blender 600W | C36: Home & Kitchen | D36: BetaTraders Islamabad | E36: Lahore Distribution Hub | F36: 437 | G36: 5480.24 | H36: 14347.04 | I36: 45503 | J36: 94 | K36: 3.93 | L36: 22 | M36: 19 | N36: 105 | O36: 45330
A37: SKU-5000 | B37: Smart Plug 4-pack | C37: Electronics | D37: MedPlus Distributors | E37: Lahore Distribution Hub | F37: 263 | G37: 8157.75 | H37: 12954.15 | I37: 45409 | J37: 9 | K37: 0.83 | L37: 19 | M37: 40 | N37: 56 | O37: 45552
A39: SKU-5026 | B39: Baseball Cap | C39: Clothing | D39: AlphaSupplies Lahore | E39: Karachi North Depot | F39: 396 | G39: 10046.26 | H39: 22474.3 | I39: 45705 | J39: 115 | K39: 3.28 | L39: 10 | M39: 24 | N39: 57 | O39: 45534
A40: SKU-5063 | B40: Speed Jump Rope | C40: Sports & Outdoor | D40: TechWorld Pvt Ltd | E40: Islamabad Storage | F40: 239 | G40: 2205.78 | H40: 2992.08 | I40: 45749 | J40: 92 | K40: 7.74 | L40: 26 | M40: 30 | N40: 231 | O40: 45486
A41: SKU-5054 | B41: Lip Balm SPF Pack | C41: Health & Beauty | D41: BetaTraders Islamabad | E41: Karachi North Depot | F41: 337 | G41: 6084.05 | H41: 10669.68 | I41: 45733 | J41: 89 | K41: 1.91 | L41: 12 | M41: 29 | N41: 52 | O41: 45421
A42: SKU-5031 | B42: Non-Stick Pan Set 3pc | C42: Home & Kitchen | D42: TechWorld Pvt Ltd | E42: Karachi North Depot | F42: 425 | G42: 12537 | H42: 15394.24 | I42: 45487 | J42: 59 | K42: 1.69 | L42: 18 | M42: 8 | N42: 38 | O42: 45516
A43: SKU-5066 | B43: Running Shoes Size 42 | C43: Sports & Outdoor | D43: AlphaSupplies Lahore | E43: Islamabad Storage | F43: 294 | G43: 15031.42 | H43: 40548.9 | I43: 45711 | J43: 47 | K43: 3.59 | L43: 11 | M43: 33 | N43: 72 | O43: 45729
A44: SKU-5042 | B44: Induction Cooker | C44: Home & Kitchen | D44: SportZone Pakistan | E44: Lahore Distribution Hub | F44: 206 | G44: 9514.77 | H44: 12263.43 | I44: 45750 | J44: 46 | K44: 0.16 | L44: 10 | M44: 24 | N44: 26 | O44: 45434
A45: SKU-5028 | B45: Gym Shorts | C45: Clothing | D45: FashionHub Karachi | E45: Karachi North Depot | F45: 597 | G45: 11061.24 | H45: 20851.53 | I45: 45440 | J45: 89 | K45: 3.23 | L45: 17 | M45: 36 | N45: 91 | O45: 45648
A46: SKU-5017 | B46: Slim Denim Jeans | C46: Clothing | D46: FashionHub Karachi | E46: Lahore Distribution Hub | F46: -20 | G46: 11672.19 | H46: 31290.23 | I46: 45693 | J46: 72 | K46: 4.32 | L46: 8 | M46: 9 | N46: 44 | O46: 45571
A47: SKU-5064 | B47: Water Bottle 1L Steel | C47: Sports & Outdoor | D47: FashionHub Karachi | E47: Karachi North Depot | F47: 388 | G47: 12159.99 | H47: 25561.04 | I47: 45495 | J47: 29 | K47: 4.98 | L47: 20 | M47: 6 | N47: 106 | O47: 45295
... A75: SKU-5018 | B75: Casual Sneakers | C75: Clothing | D75: HomeEssentials Co. | E75: Islamabad Storage | F75: -18 | G75: 15032.35 | H75: 32283.76 | I75: 45700 | J75: 38 | K75: 7.51 | L75: 34 | M75: 11 | N75: 266 | O75: 45616
...

Sheet RAW_DATA
A1: SKU | B1: Product_Name | C1: Category | D1: Supplier | E1: Warehouse | F1: Quantity_On_Hand | G1: Cost_Price_PKR | H1: Selling_Price_PKR | I1: Last_Sale_Date | J1: Units_Sold_Last_90Days | K1: Avg_Daily_Sales | L1: Lead_Time_Days | M1: Safety_Stock_Units | N1: Reorder_Point | O1: Last_Restock_Date
A2: SKU-5035 | B2: Electric Kettle 1.7L | C2: Home & Kitchen | D2: FashionHub Karachi | E2: Lahore Distribution Hub | F2: 125 | G2: 11240.84 | H2: 21532.76 | I2: 45673 | J2: 27 | K2: 6.15 | L2: 19 | M2: 21 | N2: 138 | O2: 45601
A3: SKU-5050 | B3: Multivitamin 60 Tabs | C3: Health & Beauty | D3: GammaSources Karachi | E3: Karachi North Depot | F3: 266 | G3: 13724.92 | H3: 10571.67 | J3: 98 | K3: 6.61 | L3: 17 | M3: 37 | N3: 149 | O3: 45733
A4: SKU-5057 | B4: Nail Kit Manicure | C4: Health & Beauty | D4: TechWorld Pvt Ltd | E4: Islamabad Storage | F4: 108 | G4: 5279.72 | H4: 6714.94 | I4: 45745 | J4: 90 | K4: 3.58 | L4: 32 | M4: 11 | N4: 126 | O4: 45577
A5: SKU-5070 | B5: Tennis Ball Pack 3 | C5: Sports & Outdoor | D5: GammaSources Karachi | E5: Karachi Central Warehouse | F5: 316 | G5: 13131.29 | H5: 29242.82 | I5: 45661 | J5: 3 | K5: 6.79 | L5: 6 | M5: 35 | N5: 76 | O5: 45300
A6: SKU-5024 | B6: Zip Hoodie | C6: Clothing | D6: MedPlus Distributors | E6: Islamabad Storage | F6: 119 | G6: 3337.44 | H6: 5226.38 | I6: 45766 | J6: 44 | K6: 3.52 | L6: 28 | M6: 25 | N6: 124 | O6: 45738
A7: SKU-5025 | B7: Socks 6-pack | C7: Clothing | D7: SportZone Pakistan | E7: Karachi North Depot | F7: 209 | G7: 9430.58 | H7: 21444.38 | I7: 45774 | J7: 8 | K7: 5 | L7: 35 | M7: 26 | N7: 201 | O7: 45593
A8: SKU-5014 | B8: Dash Cam | C8: Electronics | D8: GammaSources Karachi | E8: Lahore Distribution Hub | F8: 10 | G8: 15584.01 | H8: 21764.48 | I8: 45738 | J8: 33 | K8: 2.32 | L8: 34 | M8: 34 | N8: 113 | O8: 45663
A9: SKU-5055 | B9: Face Wash Neem | C9: Health & Beauty | D9: HomeEssentials Co. | E9: Karachi North Depot | F9: 522 | G9: 17657.6 | H9: 20874.69 | I9: 45754 | J9: 42 | K9: 7 | L9: 32 | M9: 11 | N9: 235 | O9: 45315
A10: SKU-5037 | B10: Rice Cooker 1.8L | C10: Home & Kitchen | D10: GammaSources Karachi | E10: Lahore Distribution Hub | F10: 78 | G10: 883.08 | H10: 1970.47 | I10: 45749 | J10: 43 | K10: 6.59 | L10: 5 | M10: 31 | N10: 64 | O10: 45538
A11: SKU-5045 | B11: Face Moisturizer SPF30 | C11: Health & Beauty | D11: HomeEssentials Co. | E11: Karachi Central Warehouse | F11: 109 | G11: 5601.04 | H11: 12009.64 | I11: 45761 | J11: 26 | K11: 2.15 | L11: 25 | M11: 18 | N11: 72 | O11: 45551
A12: SKU-5067 | B12: Badminton Racket Set | C12: Sports & Outdoor | D12: MedPlus Distributors | E12: Karachi Central Warehouse | F12: 101 | G12: 17432.49 | H12: 43662.13 | I12: 45708 | J12: 82 | K12: 0.45 | L12: 25 | M12: 6 | N12: 17 | O12: 45336
A13: SKU-5004 | B13: Power Bank 20000mAh | C13: Electronics | D13: SportZone Pakistan | E13: Karachi Central Warehouse | F13: 578 | G13: 8401.34 | H13: 22470.7 | J13: 41 | K13: 1.87 | L13: 31 | M13: 8 | N13: 66 | O13: 45652
A14: SKU-5002 | B14: USB-C Hub | C14: Electronics | D14: MedPlus Distributors | E14: Karachi Central Warehouse | F14: 557 | G14: 10926.51 | H14: 25633.04 | I14: 45703 | J14: 118 | K14: 4.44 | L14: 17 | M14: 10 | N14: 85 | O14: 45737
A15: SKU-5059 | B15: Collagen Supplement | C15: Health & Beauty | D15: GammaSources Karachi | E15: Islamabad Storage | F15: 567 | G15: 16195.52 | H15: 25965 | I15: 45714 | J15: 56 | K15: 7.9 | L15: 35 | M15: 27 | N15: 304 | O15: 45659
A16: SKU-5030 | B16: Pressure Cooker 5L | C16: Home & Kitchen | D16: AlphaSupplies Lahore | E16: Karachi Central Warehouse | F16: 291 | G16: 8183.75 | H16: 20712.82 | I16: 45440 | J16: 66 | K16: 2.23 | L16: 20 | M16: 20 | N16: 65 | O16: 45690
A18: SKU-5006 | B18: Webcam HD 1080p | C18: Electronics | D18: SportZone Pakistan | E18: Karachi Central Warehouse | F18: 120 | G18: 9245.04 | H18: 11086.24 | I18: 45613 | J18: 20 | K18: 4.79 | L18: 30 | M18: 32 | N18: 176 | O18: 45412
A20: SKU-5060 | B20: Yoga Mat 6mm | C20: Sports & Outdoor | D20: TechWorld Pvt Ltd | E20: Karachi North Depot | F20: 596 | G20: 8775.26 | H20: 18259.83 | I20: 45747 | J20: 89 | K20: 7.82 | L20: 14 | M20: 6 | N20: 115 | O20: 45334
A21: SKU-5012 | B21: Router WiFi 6 | C21: Electronics | D21: AlphaSupplies Lahore | E21: Karachi Central Warehouse | F21: 441 | G21: 3548.82 | H21: 6544.61 | I21: 45731 | J21: 110 | K21: 5.4 | L21: 28 | M21: 8 | N21: 159 | O21: 45633
A22: SKU-5033 | B22: Water Filter Jug | C22: Home & Kitchen | D22: MedPlus Distributors | E22: Karachi North Depot | F22: 585 | G22: 17655.89 | H22: 46675.83 | I22: 45740 | J22: 10 | K22: 1.13 | L22: 25 | M22: 32 | N22: 60 | O22: 45593
A23: SKU-5001 | B23: Bluetooth Speaker | C23: Electronics | D23: FashionHub Karachi | E23: Karachi North Depot | F23: 14 | G23: 7638.43 | H23: 12124.94 | I23: 45404 | J23: 20 | K23: 2.75 | L23: 27 | M23: 32 | N23: 106 | O23: 45711
A24: SKU-5029 | B24: Thermal Underwear | C24: Clothing | D24: BetaTraders Islamabad | E24: Karachi North Depot | F24: 132 | G24: 8442.22 | H24: 22467.7 | I24: 45418 | J24: 102 | K24: 7.9 | L24: 19 | M24: 38 | N24: 188 | O24: 45301
A25: SKU-5040 | B25: Knife Set 5pc | C25: Home & Kitchen | D25: GammaSources Karachi | E25: Islamabad Storage | F25: 510 | G25: 8871.11 | H25: 20228.12 | I25: 45475 | J25: 2 | K25: 1.81 | L25: 7 | M25: 23 | N25: 36 | O25: 45543
A26: SKU-5016 | B26: Women Kurta Embroidered | C26: Clothing | D26: AlphaSupplies Lahore | E26: Lahore Distribution Hub | F26: 600 | G26: 7357.39 | H26: 15281.7 | I26: 45563 | J26: 79 | K26: 5.28 | L26: 7 | M26: 31 | N26: 68 | O26: 45625
A27: SKU-5015 | B27: Men Polo Shirt | C27: Clothing | D27: HomeEssentials Co. | E27: Karachi Central Warehouse | F27: 329 | G27: 1193.93 | H27: 1459.47 | I27: 45684 | J27: 74 | K27: 7.36 | L27: 20 | M27: 37 | N27: 184 | O27: 45456
... A33: SKU-5041 | B33: Food Storage Containers | C33: Home & Kitchen | D33: MedPlus Distributors | E33: Karachi North Depot | F33: 265 | G33: 6054.62 | H33: 9536.87 | I33: 45757 | J33: 92 | K33: 1 | L33: 11 | M33: 25 | N33: 36 | O33: 45619
A34: SKU-5022 | B34: Formal Trousers | C34: Clothing | D34: MedPlus Distributors | E34: Karachi North Depot | F34: 262 | G34: 16765.06 | H34: 43113.49 | J34: 100 | K34: 3.09 | L34: 27 | M34: 11 | N34: 94 | O34: 45581
A35: SKU-5007 | B35: Gaming Mouse | C35: Electronics | D35: HomeEssentials Co. | E35: Karachi Central Warehouse | F35: 356 | G35: 15943.47 | H35: 38443.63 | I35: 45753 | J35: 55 | K35: 0.08 | L35: 10 | M35: 34 | N35: 35 | O35: 45315
A36: SKU-5032 | B36: Blender 600W | C36: Home & Kitchen | D36: BetaTraders Islamabad | E36: Lahore Distribution Hub | F36: 437 | G36: 5480.24 | H36: 14347.04 | I36: 45503 | J36: 94 | K36: 3.93 | L36: 22 | M36: 19 | N36: 105 | O36: 45330
A37: SKU-5000 | B37: Smart Plug 4-pack | C37: Electronics | D37: MedPlus Distributors | E37: Lahore Distribution Hub | F37: 263 | G37: 8157.75 | H37: 12954.15 | I37: 45409 | J37: 9 | K37: 0.83 | L37: 19 | M37: 40 | N37: 56 | O37: 45552
A39: SKU-5026 | B39: Baseball Cap | C39: Clothing | D39: AlphaSupplies Lahore | E39: Karachi North Depot | F39: 396 | G39: 10046.26 | H39: 22474.3 | I39: 45705 | J39: 115 | K39: 3.28 | L39: 10 | M39: 24 | N39: 57 | O39: 45534
A40: SKU-5063 | B40: Speed Jump Rope | C40: Sports & Outdoor | D40: TechWorld Pvt Ltd | E40: Islamabad Storage | F40: 239 | G40: 2205.78 | H40: 2992.08 | I40: 45749 | J40: 92 | K40: 7.74 | L40: 26 | M40: 30 | N40: 231 | O40: 45486
A41: SKU-5054 | B41: Lip Balm SPF Pack | C41: Health & Beauty | D41: BetaTraders Islamabad | E41: Karachi North Depot | F41: 337 | G41: 6084.05 | H41: 10669.68 | I41: 45733 | J41: 89 | K41: 1.91 | L41: 12 | M41: 29 | N41: 52 | O41: 45421
A42: SKU-5031 | B42: Non-Stick Pan Set 3pc | C42: Home & Kitchen | D42: TechWorld Pvt Ltd | E42: Karachi North Depot | F42: 425 | G42: 12537 | H42: 15394.24 | I42: 45487 | J42: 59 | K42: 1.69 | L42: 18 | M42: 8 | N42: 38 | O42: 45516
A43: SKU-5066 | B43: Running Shoes Size 42 | C43: Sports & Outdoor | D43: AlphaSupplies Lahore | E43: Islamabad Storage | F43: 294 | G43: 15031.42 | H43: 40548.9 | I43: 45711 | J43: 47 | K43: 3.59 | L43: 11 | M43: 33 | N43: 72 | O43: 45729
A44: SKU-5042 | B44: Induction Cooker | C44: Home & Kitchen | D44: SportZone Pakistan | E44: Lahore Distribution Hub | F44: 206 | G44: 9514.77 | H44: 12263.43 | I44: 45750 | J44: 46 | K44: 0.16 | L44: 10 | M44: 24 | N44: 26 | O44: 45434
A45: SKU-5028 | B45: Gym Shorts | C45: Clothing | D45: FashionHub Karachi | E45: Karachi North Depot | F45: 597 | G45: 11061.24 | H45: 20851.53 | I45: 45440 | J45: 89 | K45: 3.23 | L45: 17 | M45: 36 | N45: 91 | O45: 45648
A46: SKU-5017 | B46: Slim Denim Jeans | C46: Clothing | D46: FashionHub Karachi | E46: Lahore Distribution Hub | F46: -20 | G46: 11672.19 | H46: 31290.23 | I46: 45693 | J46: 72 | K46: 4.32 | L46: 8 | M46: 9 | N46: 44 | O46: 45571
A47: SKU-5064 | B47: Water Bottle 1L Steel | C47: Sports & Outdoor | D47: FashionHub Karachi | E47: Karachi North Depot | F47: 388 | G47: 12159.99 | H47: 25561.04 | I47: 45495 | J47: 29 | K47: 4.98 | L47: 20 | M47: 6 | N47: 106 | O47: 45295
... A75: SKU-5018 | B75: Casual Sneakers | C75: Clothing | D75: HomeEssentials Co. | E75: Islamabad Storage | F75: -18 | G75: 15032.35 | H75: 32283.76 | I75: 45700 | J75: 38 | K75: 7.51 | L75: 34 | M75: 11 | N75: 266 | O75: 45616
...

Sheet CLEANED
A1: SKU | B1: Product_Name | C1: Category | D1: Supplier | E1: Warehouse | F1: Quantity_On_Hand | G1: Cost_Price_PKR | H1: Selling_Price_PKR | I1: Last_Sale_Date | J1: Units_Sold_Last_90Days | K1: Avg_Daily_Sales | L1: Lead_Time_Days | M1: Safety_Stock_Units | N1: Reorder_Point | O1: Last_Restock_Date | P1: Last_Sale_Date_Flag | Q1: Quantity_Flag | R1: Margin_Flag | S1: Duplicate_SKU_Check
A2: SKU-5035 | B2: Electric Kettle 1.7L | C2: Home & Kitchen | D2: FashionHub Karachi | E2: Lahore Distribution Hub | F2: 125 | G2: 11240.84 | H2: 21532.76 | I2: 45673 | J2: 27 | K2: 6.15 | L2: 19 | M2: 21 | N2: 138 | O2: 45601 | P2: =IF(I2=DATE(2020,1,1),"NO SALE RECORDED","OK") -> OK | Q2: =IF(F2<0,"NEGATIVE QTY - DATA ERROR","OK") -> OK | R2: =IF(G2>H2,"SELLING AT LOSS - REVIEW PRICING","OK") -> OK | S2: =IF(COUNTIF($A$2:$A$76,A2)>1,"DUPLICATE SKU","UNIQUE") -> UNIQUE
A3: SKU-5050 | B3: Multivitamin 60 Tabs | C3: Health & Beauty | D3: GammaSources Karachi | E3: Karachi North Depot | F3: 266 | G3: 13724.92 | H3: 10571.67 | I3: 43831 | J3: 98 | K3: 6.61 | L3: 17 | M3: 37 | N3: 149 | O3: 45733 | P3: =IF(I3=DATE(2020,1,1),"NO SALE RECORDED","OK") -> NO SALE RECORDED | Q3: =IF(F3<0,"NEGATIVE QTY - DATA ERROR","OK") -> OK | R3: =IF(G3>H3,"SELLING AT LOSS - REVIEW PRICING","OK") -> SELLING AT LOSS - REVIEW PRICING | S3: =IF(COUNTIF($A$2:$A$76,A3)>1,"DUPLICATE SKU","UNIQUE") -> UNIQUE
A4: SKU-5057 | B4: Nail Kit Manicure | C4: Health & Beauty | D4: TechWorld Pvt Ltd | E4: Islamabad Storage | F4: 108 | G4: 5279.72 | H4: 6714.94 | I4: 45745 | J4: 90 | K4: 3.58 | L4: 32 | M4: 11 | N4: 126 | O4: 45577 | P4: =IF(I4=DATE(2020,1,1),"NO SALE RECORDED","OK") -> OK | Q4: =IF(F4<0,"NEGATIVE QTY - DATA ERROR","OK") -> OK | R4: =IF(G4>H4,"SELLING AT LOSS - REVIEW PRICING","OK") -> OK | S4: =IF(COUNTIF($A$2:$A$76,A4)>1,"DUPLICATE SKU","UNIQUE") -> UNIQUE
A5: SKU-5070 | B5: Tennis Ball Pack 3 | C5: Sports & Outdoor | D5: GammaSources Karachi | E5: Karachi Central Warehouse | F5: 316 | G5: 13131.29 | H5: 29242.82 | I5: 45661 | J5: 3 | K5: 6.79 | L5: 6 | M5: 35 | N5: 76 | O5: 45300 | P5: =IF(I5=DATE(2020,1,1),"NO SALE RECORDED","OK") -> OK | Q5: =IF(F5<0,"NEGATIVE QTY - DATA ERROR","OK") -> OK | R5: =IF(G5>H5,"SELLING AT LOSS - REVIEW PRICING","OK") -> OK | S5: =IF(COUNTIF($A$2:$A$76,A5)>1,"DUPLICATE SKU","UNIQUE") -> UNIQUE
A6: SKU-5024 | B6: Zip Hoodie | C6: Clothing | D6: MedPlus Distributors | E6: Islamabad Storage | F6: 119 | G6: 3337.44 | H6: 5226.38 | I6: 45766 | J6: 44 | K6: 3.52 | L6: 28 | M6: 25 | N6: 124 | O6: 45738 | P6: =IF(I6=DATE(2020,1,1),"NO SALE RECORDED","OK") -> OK | Q6: =IF(F6<0,"NEGATIVE QTY - DATA ERROR","OK") -> OK | R6: =IF(G6>H6,"SELLING AT LOSS - REVIEW PRICING","OK") -> OK | S6: =IF(COUNTIF($A$2:$A$76,A6)>1,"DUPLICATE SKU","UNIQUE") -> UNIQUE
A7: SKU-5025 | B7: Socks 6-pack | C7: Clothing | D7: SportZone Pakistan | E7: Karachi North Depot | F7: 209 | G7: 9430.58 | H7: 21444.38 | I7: 45774 | J7: 8 | K7: 5 | L7: 35 | M7: 26 | N7: 201 | O7: 45593 | P7: =IF(I7=DATE(2020,1,1),"NO SALE RECORDED","OK") -> OK | Q7: =IF(F7<0,"NEGATIVE QTY - DATA ERROR","OK") -> OK | R7: =IF(G7>H7,"SELLING AT LOSS - REVIEW PRICING","OK") -> OK | S7: =IF(COUNTIF($A$2:$A$76,A7)>1,"DUPLICATE SKU","UNIQUE") -> UNIQUE
A8: SKU-5014 | B8: Dash Cam | C8: Electronics | D8: GammaSources Karachi | E8: Lahore Distribution Hub | F8: 10 | G8: 15584.01 | H8: 21764.48 | I8: 45738 | J8: 33 | K8: 2.32 | L8: 34 | M8: 34 | N8: 113 | O8: 45663 | P8: =IF(I8=DATE(2020,1,1),"NO SALE RECORDED","OK") -> OK | Q8: =IF(F8<0,"NEGATIVE QTY - DATA ERROR","OK") -> OK | R8: =IF(G8>H8,"SELLING AT LOSS - REVIEW PRICING","OK") -> OK | S8: =IF(COUNTIF($A$2:$A$76,A8)>1,"DUPLICATE SKU","UNIQUE") -> UNIQUE
A9: SKU-5055 | B9: Face Wash Neem | C9: Health & Beauty | D9: HomeEssentials Co. | E9: Karachi North Depot | F9: 522 | G9: 17657.6 | H9: 20874.69 | I9: 45754 | J9: 42 | K9: 7 | L9: 32 | M9: 11 | N9: 235 | O9: 45315 | P9: =IF(I9=DATE(2020,1,1),"NO SALE RECORDED","OK") -> OK | Q9: =IF(F9<0,"NEGATIVE QTY - DATA ERROR","OK") -> OK | R9: =IF(G9>H9,"SELLING AT LOSS - REVIEW PRICING","OK") -> OK | S9: =IF(COUNTIF($A$2:$A$76,A9)>1,"DUPLICATE SKU","UNIQUE") -> UNIQUE
A10: SKU-5037 | B10: Rice Cooker 1.8L | C10: Home & Kitchen | D10: GammaSources Karachi | E10: Lahore Distribution Hub | F10: 78 | G10: 883.08 | H10: 1970.47 | I10: 45749 | J10: 43 | K10: 6.59 | L10: 5 | M10: 31 | N10: 64 | O10: 45538 | P10: =IF(I10=DATE(2020,1,1),"NO SALE RECORDED","OK") -> OK | Q10: =IF(F10<0,"NEGATIVE QTY - DATA ERROR","OK") -> OK | R10: =IF(G10>H10,"SELLING AT LOSS - REVIEW PRICING","OK") -> OK | S10: =IF(COUNTIF($A$2:$A$76,A10)>1,"DUPLICATE SKU","UNIQUE") -> UNIQUE
A11: SKU-5045 | B11: Face Moisturizer SPF30 | C11: Health & Beauty | D11: HomeEssentials Co. | E11: Karachi Central Warehouse | F11: 109 | G11: 5601.04 | H11: 12009.64 | I11: 45761 | J11: 26 | K11: 2.15 | L11: 25 | M11: 18 | N11: 72 | O11: 45551 | P11: =IF(I11=DATE(2020,1,1),"NO SALE RECORDED","OK") -> OK | Q11: =IF(F11<0,"NEGATIVE QTY - DATA ERROR","OK") -> OK | R11: =IF(G11>H11,"SELLING AT LOSS - REVIEW PRICING","OK") -> OK | S11: =IF(COUNTIF($A$2:$A$76,A11)>1,"DUPLICATE SKU","UNIQUE") -> UNIQUE
A12: SKU-5067 | B12: Badminton Racket Set | C12: Sports & Outdoor | D12: MedPlus Distributors | E12: Karachi Central Warehouse | F12: 101 | G12: 17432.49 | H12: 43662.13 | I12: 45708 | J12: 82 | K12: 0.45 | L12: 25 | M12: 6 | N12: 17 | O12: 45336 | P12: =IF(I12=DATE(2020,1,1),"NO SALE RECORDED","OK") -> OK | Q12: =IF(F12<0,"NEGATIVE QTY - DATA ERROR","OK") -> OK | R12: =IF(G12>H12,"SELLING AT LOSS - REVIEW PRICING","OK") -> OK | S12: =IF(COUNTIF($A$2:$A$76,A12)>1,"DUPLICATE SKU","UNIQUE") -> UNIQUE
A13: SKU-5004 | B13: Power Bank 20000mAh | C13: Electronics | D13: SportZone Pakistan | E13: Karachi Central Warehouse | F13: 578 | G13: 8401.34 | H13: 22470.7 | I13: 43831 | J13: 41 | K13: 1.87 | L13: 31 | M13: 8 | N13: 66 | O13: 45652 | P13: =IF(I13=DATE(2020,1,1),"NO SALE RECORDED","OK") -> NO SALE RECORDED | Q13: =IF(F13<0,"NEGATIVE QTY - DATA ERROR","OK") -> OK | R13: =IF(G13>H13,"SELLING AT LOSS - REVIEW PRICING","OK") -> OK | S13: =IF(COUNTIF($A$2:$A$76,A13)>1,"DUPLICATE SKU","UNIQUE") -> UNIQUE
... A76: SKU-5023 | B76: Summer Dress Floral | C76: Clothing | D76: AlphaSupplies Lahore | E76: Karachi Central Warehouse | F76: 416 | G76: 15703.12 | H76: 34999.99 | I76: 45689 | J76: 110 | K76: 2.84 | L76: 7 | M76: 22 | N76: 42 | O76: 45701 | P76: =IF(I76=DATE(2020,1,1),"NO SALE RECORDED","OK") -> OK | Q76: =IF(F76<0,"NEGATIVE QTY - DATA ERROR","OK") -> OK | R76: =IF(G76>H76,"SELLING AT LOSS - REVIEW PRICING","OK") -> OK | S76: =IF(COUNTIF($A$2:$A$76,A76)>1,"DUPLICATE SKU","UNIQUE") -> UNIQUE

Sheet ANALYSIS
A1: INVENTORY HEALTH & DEAD STOCK ANALYSIS | Q1: Analysis_Date | R1: =DATE(2025,5,10) -> 45787
Q2: Note: Analysis date set to 10-May-2025 to cover all sale dates in dataset. Original attempt used 28-Apr-2025 which caused negative days for 1 product sold on 03-May-2025.
A3: SKU | B3: Product_Name | C3: Category | D3: Quantity_On_Hand | E3: Cost_Price_PKR | F3: Selling_Price_PKR | G3: Last_Sale_Date | H3: Days_Since_Last_Sale | I3: Aging_Bucket | J3: Cash_Tied_Up_PKR | K3: Turnover_Ratio | L3: Reorder_Status | M3: Last_Sale_Flag | N3: Quantity_Flag | O3: Margin_Flag
A4: =CLEANED!A2 -> SKU-5035 | B4: =CLEANED!B2 -> Electric Kettle 1.7L | C4: =CLEANED!C2 -> Home & Kitchen | D4: =CLEANED!F2 -> 125 | E4: =CLEANED!G2 -> 11240.84 | F4: =CLEANED!H2 -> 21532.76 | G4: =CLEANED!I2 -> 45673 | H4: =IF(M4="NO SALE RECORDED","No Sale Record",$R$1-G4) -> 114 | I4: =IF(H4="No Sale Record","🔴 Dead - No Sale",IF(H4>90,"🔴 Dead (90+ Days)",IF(H4>60,"🟡 At Risk (61-90 Days)",IF(H4>30,"🟠 Slow (31-60 Days)","🟢 Active (0-30 Days)")))) -> 🔴 Dead (90+ Days) | J4: =IF(N4="NEGATIVE QTY - DATA ERROR",0,D4*E4) -> 1405105 | K4: =IF(OR(D4<=0,N4="NEGATIVE QTY - DATA ERROR"),0,CLEANED!J2/D4) -> 0.216 | L4: =IF(N4="NEGATIVE QTY - DATA ERROR","Data Error",IF(D4<=CLEANED!N2,"⚠️ Below Reorder Point - Restock Now",IF(AND(H4>90,D4>CLEANED!N2*2),"📦 Overstocked & Dead","✅ Stock Level OK"))) -> ⚠️ Below Reorder Point - Restock Now | M4: =CLEANED!P2 -> OK | N4: =CLEANED!Q2 -> OK | O4: =CLEANED!R2 -> OK
A5: =CLEANED!A3 -> SKU-5050 | B5: =CLEANED!B3 -> Multivitamin 60 Tabs | C5: =CLEANED!C3 -> Health & Beauty | D5: =CLEANED!F3 -> 266 | E5: =CLEANED!G3 -> 13724.92 | F5: =CLEANED!H3 -> 10571.67 | G5: =CLEANED!I3 -> 43831 | H5: =IF(M5="NO SALE RECORDED","No Sale Record",$R$1-G5) -> No Sale Record | I5: =IF(H5="No Sale Record","🔴 Dead - No Sale",IF(H5>90,"🔴 Dead (90+ Days)",IF(H5>60,"🟡 At Risk (61-90 Days)",IF(H5>30,"🟠 Slow (31-60 Days)","🟢 Active (0-30 Days)")))) -> 🔴 Dead - No Sale | J5: =IF(N5="NEGATIVE QTY - DATA ERROR",0,D5*E5) -> 3650828.7 | K5: =IF(OR(D5<=0,N5="NEGATIVE QTY - DATA ERROR"),0,CLEANED!J3/D5) -> 0.36842105 | L5: =IF(N5="NEGATIVE QTY - DATA ERROR","Data Error",IF(D5<=CLEANED!N3,"⚠️ Below Reorder Point - Restock Now",IF(AND(H5>90,D5>CLEANED!N3*2),"📦 Overstocked & Dead","✅ Stock Level OK"))) -> ✅ Stock Level OK | M5: =CLEANED!P3 -> NO SALE RECORDED | N5: =CLEANED!Q3 -> OK | O5: =CLEANED!R3 -> SELLING AT LOSS - REVIEW PRICING
A6: =CLEANED!A4 -> SKU-5057 | B6: =CLEANED!B4 -> Nail Kit Manicure | C6: =CLEANED!C4 -> Health & Beauty | D6: =CLEANED!F4 -> 108 | E6: =CLEANED!G4 -> 5279.72 | F6: =CLEANED!H4 -> 6714.94 | G6: =CLEANED!I4 -> 45745 | H6: =IF(M6="NO SALE RECORDED","No Sale Record",$R$1-G6) -> 42 | I6: =IF(H6="No Sale Record","🔴 Dead - No Sale",IF(H6>90,"🔴 Dead (90+ Days)",IF(H6>60,"🟡 At Risk (61-90 Days)",IF(H6>30,"🟠 Slow (31-60 Days)","🟢 Active (0-30 Days)")))) -> 🟠 Slow (31-60 Days) | J6: =IF(N6="NEGATIVE QTY - DATA ERROR",0,D6*E6) -> 570209.76 | K6: =IF(OR(D6<=0,N6="NEGATIVE QTY - DATA ERROR"),0,CLEANED!J4/D6) -> 0.83333333 | L6: =IF(N6="NEGATIVE QTY - DATA ERROR","Data Error",IF(D6<=CLEANED!N4,"⚠️ Below Reorder Point - Restock Now",IF(AND(H6>90,D6>CLEANED!N4*2),"📦 Overstocked & Dead","✅ Stock Level OK"))) -> ⚠️ Below Reorder Point - Restock Now | M6: =CLEANED!P4 -> OK | N6: =CLEANED!Q4 -> OK | O6: =CLEANED!R4 -> OK
A7: =CLEANED!A5 -> SKU-5070 | B7: =CLEANED!B5 -> Tennis Ball Pack 3 | C7: =CLEANED!C5 -> Sports & Outdoor | D7: =CLEANED!F5 -> 316 | E7: =CLEANED!G5 -> 13131.29 | F7: =CLEANED!H5 -> 29242.82 | G7: =CLEANED!I5 -> 45661 | H7: =IF(M7="NO SALE RECORDED","No Sale Record",$R$1-G7) -> 126 | I7: =IF(H7="No Sale Record","🔴 Dead - No Sale",IF(H7>90,"🔴 Dead (90+ Days)",IF(H7>60,"🟡 At Risk (61-90 Days)",IF(H7>30,"🟠 Slow (31-60 Days)","🟢 Active (0-30 Days)")))) -> 🔴 Dead (90+ Days) | J7: =IF(N7="NEGATIVE QTY - DATA ERROR",0,D7*E7) -> 4149487.6 | K7: =IF(OR(D7<=0,N7="NEGATIVE QTY - DATA ERROR"),0,CLEANED!J5/D7) -> 0.0094936709 | L7: =IF(N7="NEGATIVE QTY - DATA ERROR","Data Error",IF(D7<=CLEANED!N5,"⚠️ Below Reorder Point - Restock Now",IF(AND(H7>90,D7>CLEANED!N5*2),"📦 Overstocked & Dead","✅ Stock Level OK"))) -> 📦 Overstocked & Dead | M7: =CLEANED!P5 -> OK | N7: =CLEANED!Q5 -> OK | O7: =CLEANED!R5 -> OK
A8: =CLEANED!A6 -> SKU-5024 | B8: =CLEANED!B6 -> Zip Hoodie | C8: =CLEANED!C6 -> Clothing | D8: =CLEANED!F6 -> 119 | E8: =CLEANED!G6 -> 3337.44 | F8: =CLEANED!H6 -> 5226.38 | G8: =CLEANED!I6 -> 45766 | H8: =IF(M8="NO SALE RECORDED","No Sale Record",$R$1-G8) -> 21 | I8: =IF(H8="No Sale Record","🔴 Dead - No Sale",IF(H8>90,"🔴 Dead (90+ Days)",IF(H8>60,"🟡 At Risk (61-90 Days)",IF(H8>30,"🟠 Slow (31-60 Days)","🟢 Active (0-30 Days)")))) -> 🟢 Active (0-30 Days) | J8: =IF(N8="NEGATIVE QTY - DATA ERROR",0,D8*E8) -> 397155.36 | K8: =IF(OR(D8<=0,N8="NEGATIVE QTY - DATA ERROR"),0,CLEANED!J6/D8) -> 0.3697479 | L8: =IF(N8="NEGATIVE QTY - DATA ERROR","Data Error",IF(D8<=CLEANED!N6,"⚠️ Below Reorder Point - Restock Now",IF(AND(H8>90,D8>CLEANED!N6*2),"📦 Overstocked & Dead","✅ Stock Level OK"))) -> ⚠️ Below Reorder Point - Restock Now | M8: =CLEANED!P6 -> OK | N8: =CLEANED!Q6 -> OK | O8: =CLEANED!R6 -> OK
A9: =CLEANED!A7 -> SKU-5025 | B9: =CLEANED!B7 -> Socks 6-pack | C9: =CLEANED!C7 -> Clothing | D9: =CLEANED!F7 -> 209 | E9: =CLEANED!G7 -> 9430.58 | F9: =CLEANED!H7 -> 21444.38 | G9: =CLEANED!I7 -> 45774 | H9: =IF(M9="NO SALE RECORDED","No Sale Record",$R$1-G9) -> 13 | I9: =IF(H9="No Sale Record","🔴 Dead - No Sale",IF(H9>90,"🔴 Dead (90+ Days)",IF(H9>60,"🟡 At Risk (61-90 Days)",IF(H9>30,"🟠 Slow (31-60 Days)","🟢 Active (0-30 Days)")))) -> 🟢 Active (0-30 Days) | J9: =IF(N9="NEGATIVE QTY - DATA ERROR",0,D9*E9) -> 1970991.2 | K9: =IF(OR(D9<=0,N9="NEGATIVE QTY - DATA ERROR"),0,CLEANED!J7/D9) -> 0.038277512 | L9: =IF(N9="NEGATIVE QTY - DATA ERROR","Data Error",IF(D9<=CLEANED!N7,"⚠️ Below Reorder Point - Restock Now",IF(AND(H9>90,D9>CLEANED!N7*2),"📦 Overstocked & Dead","✅ Stock Level OK"))) -> ✅ Stock Level OK | M9: =CLEANED!P7 -> OK | N9: =CLEANED!Q7 -> OK | O9: =CLEANED!R7 -> OK
A10: =CLEANED!A8 -> SKU-5014 | B10: =CLEANED!B8 -> Dash Cam | C10: =CLEANED!C8 -> Electronics | D10: =CLEANED!F8 -> 10 | E10: =CLEANED!G8 -> 15584.01 | F10: =CLEANED!H8 -> 21764.48 | G10: =CLEANED!I8 -> 45738 | H10: =IF(M10="NO SALE RECORDED","No Sale Record",$R$1-G10) -> 49 | I10: =IF(H10="No Sale Record","🔴 Dead - No Sale",IF(H10>90,"🔴 Dead (90+ Days)",IF(H10>60,"🟡 At Risk (61-90 Days)",IF(H10>30,"🟠 Slow (31-60 Days)","🟢 Active (0-30 Days)")))) -> 🟠 Slow (31-60 Days) | J10: =IF(N10="NEGATIVE QTY - DATA ERROR",0,D10*E10) -> 155840.1 | K10: =IF(OR(D10<=0,N10="NEGATIVE QTY - DATA ERROR"),0,CLEANED!J8/D10) -> 3.3 | L10: =IF(N10="NEGATIVE QTY - DATA ERROR","Data Error",IF(D10<=CLEANED!N8,"⚠️ Below Reorder Point - Restock Now",IF(AND(H10>90,D10>CLEANED!N8*2),"📦 Overstocked & Dead","✅ Stock Level OK"))) -> ⚠️ Below Reorder Point - Restock Now | M10: =CLEANED!P8 -> OK | N10: =CLEANED!Q8 -> OK | O10: =CLEANED!R8 -> OK
A11: =CLEANED!A9 -> SKU-5055 | B11: =CLEANED!B9 -> Face Wash Neem | C11: =CLEANED!C9 -> Health & Beauty | D11: =CLEANED!F9 -> 522 | E11: =CLEANED!G9 -> 17657.6 | F11: =CLEANED!H9 -> 20874.69 | G11: =CLEANED!I9 -> 45754 | H11: =IF(M11="NO SALE RECORDED","No Sale Record",$R$1-G11) -> 33 | I11: =IF(H11="No Sale Record","🔴 Dead - No Sale",IF(H11>90,"🔴 Dead (90+ Days)",IF(H11>60,"🟡 At Risk (61-90 Days)",IF(H11>30,"🟠 Slow (31-60 Days)","🟢 Active (0-30 Days)")))) -> 🟠 Slow (31-60 Days) | J11: =IF(N11="NEGATIVE QTY - DATA ERROR",0,D11*E11) -> 9217267.2 | K11: =IF(OR(D11<=0,N11="NEGATIVE QTY - DATA ERROR"),0,CLEANED!J9/D11) -> 0.08045977 | L11: =IF(N11="NEGATIVE QTY - DATA ERROR","Data Error",IF(D11<=CLEANED!N9,"⚠️ Below Reorder Point - Restock Now",IF(AND(H11>90,D11>CLEANED!N9*2),"📦 Overstocked & Dead","✅ Stock Level OK"))) -> ✅ Stock Level OK | M11: =CLEANED!P9 -> OK | N11: =CLEANED!Q9 -> OK | O11: =CLEANED!R9 -> OK
A12: =CLEANED!A10 -> SKU-5037 | B12: =CLEANED!B10 -> Rice Cooker 1.8L | C12: =CLEANED!C10 -> Home & Kitchen | D12: =CLEANED!F10 -> 78 | E12: =CLEANED!G10 -> 883.08 | F12: =CLEANED!H10 -> 1970.47 | G12: =CLEANED!I10 -> 45749 | H12: =IF(M12="NO SALE RECORDED","No Sale Record",$R$1-G12) -> 38 | I12: =IF(H12="No Sale Record","🔴 Dead - No Sale",IF(H12>90,"🔴 Dead (90+ Days)",IF(H12>60,"🟡 At Risk (61-90 Days)",IF(H12>30,"🟠 Slow (31-60 Days)","🟢 Active (0-30 Days)")))) -> 🟠 Slow (31-60 Days) | J12: =IF(N12="NEGATIVE QTY - DATA ERROR",0,D12*E12) -> 68880.24 | K12: =IF(OR(D12<=0,N12="NEGATIVE QTY - DATA ERROR"),0,CLEANED!J10/D12) -> 0.55128205 | L12: =IF(N12="NEGATIVE QTY - DATA ERROR","Data Error",IF(D12<=CLEANED!N10,"⚠️ Below Reorder Point - Restock Now",IF(AND(H12>90,D12>CLEANED!N10*2),"📦 Overstocked & Dead","✅ Stock Level OK"))) -> ✅ Stock Level OK | M12: =CLEANED!P10 -> OK | N12: =CLEANED!Q10 -> OK | O12: =CLEANED!R10 -> OK
A13: =CLEANED!A11 -> SKU-5045 | B13: =CLEANED!B11 -> Face Moisturizer SPF30 | C13: =CLEANED!C11 -> Health & Beauty | D13: =CLEANED!F11 -> 109 | E13: =CLEANED!G11 -> 5601.04 | F13: =CLEANED!H11 -> 12009.64 | G13: =CLEANED!I11 -> 45761 | H13: =IF(M13="NO SALE RECORDED","No Sale Record",$R$1-G13) -> 26 | I13: =IF(H13="No Sale Record","🔴 Dead - No Sale",IF(H13>90,"🔴 Dead (90+ Days)",IF(H13>60,"🟡 At Risk (61-90 Days)",IF(H13>30,"🟠 Slow (31-60 Days)","🟢 Active (0-30 Days)")))) -> 🟢 Active (0-30 Days) | J13: =IF(N13="NEGATIVE QTY - DATA ERROR",0,D13*E13) -> 610513.36 | K13: =IF(OR(D13<=0,N13="NEGATIVE QTY - DATA ERROR"),0,CLEANED!J11/D13) -> 0.23853211 | L13: =IF(N13="NEGATIVE QTY - DATA ERROR","Data Error",IF(D13<=CLEANED!N11,"⚠️ Below Reorder Point - Restock Now",IF(AND(H13>90,D13>CLEANED!N11*2),"📦 Overstocked & Dead","✅ Stock Level OK"))) -> ✅ Stock Level OK | M13: =CLEANED!P11 -> OK | N13: =CLEANED!Q11 -> OK | O13: =CLEANED!R11 -> OK
A14: =CLEANED!A12 -> SKU-5067 | B14: =CLEANED!B12 -> Badminton Racket Set | C14: =CLEANED!C12 -> Sports & Outdoor | D14: =CLEANED!F12 -> 101 | E14: =CLEANED!G12 -> 17432.49 | F14: =CLEANED!H12 -> 43662.13 | G14: =CLEANED!I12 -> 45708 | H14: =IF(M14="NO SALE RECORDED","No Sale Record",$R$1-G14) -> 79 | I14: =IF(H14="No Sale Record","🔴 Dead - No Sale",IF(H14>90,"🔴 Dead (90+ Days)",IF(H14>60,"🟡 At Risk (61-90 Days)",IF(H14>30,"🟠 Slow (31-60 Days)","🟢 Active (0-30 Days)")))) -> 🟡 At Risk (61-90 Days) | J14: =IF(N14="NEGATIVE QTY - DATA ERROR",0,D14*E14) -> 1760681.5 | K14: =IF(OR(D14<=0,N14="NEGATIVE QTY - DATA ERROR"),0,CLEANED!J12/D14) -> 0.81188119 | L14: =IF(N14="NEGATIVE QTY - DATA ERROR","Data Error",IF(D14<=CLEANED!N12,"⚠️ Below Reorder Point - Restock Now",IF(AND(H14>90,D14>CLEANED!N12*2),"📦 Overstocked & Dead","✅ Stock Level OK"))) -> ✅ Stock Level OK | M14: =CLEANED!P12 -> OK | N14: =CLEANED!Q12 -> OK | O14: =CLEANED!R12 -> OK
A15: =CLEANED!A13 -> SKU-5004 | B15: =CLEANED!B13 -> Power Bank 20000mAh | C15: =CLEANED!C13 -> Electronics | D15: =CLEANED!F13 -> 578 | E15: =CLEANED!G13 -> 8401.34 | F15: =CLEANED!H13 -> 22470.7 | G15: =CLEANED!I13 -> 43831 | H15: =IF(M15="NO SALE RECORDED","No Sale Record",$R$1-G15) -> No Sale Record | I15: =IF(H15="No Sale Record","🔴 Dead - No Sale",IF(H15>90,"🔴 Dead (90+ Days)",IF(H15>60,"🟡 At Risk (61-90 Days)",IF(H15>30,"🟠 Slow (31-60 Days)","🟢 Active (0-30 Days)")))) -> 🔴 Dead - No Sale | J15: =IF(N15="NEGATIVE QTY - DATA ERROR",0,D15*E15) -> 4855974.5 | K15: =IF(OR(D15<=0,N15="NEGATIVE QTY - DATA ERROR"),0,CLEANED!J13/D15) -> 0.070934256 | L15: =IF(N15="NEGATIVE QTY - DATA ERROR","Data Error",IF(D15<=CLEANED!N13,"⚠️ Below Reorder Point - Restock Now",IF(AND(H15>90,D15>CLEANED!N13*2),"📦 Overstocked & Dead","✅ Stock Level OK"))) -> 📦 Overstocked & Dead | M15: =CLEANED!P13 -> NO SALE RECORDED | N15: =CLEANED!Q13 -> OK | O15: =CLEANED!R13 -> OK
... A78: =CLEANED!A76 -> SKU-5023 | B78: =CLEANED!B76 -> Summer Dress Floral | C78: =CLEANED!C76 -> Clothing | D78: =CLEANED!F76 -> 416 | E78: =CLEANED!G76 -> 15703.12 | F78: =CLEANED!H76 -> 34999.99 | G78: =CLEANED!I76 -> 45689 | H78: =IF(M78="NO SALE RECORDED","No Sale Record",$R$1-G78) -> 98 | I78: =IF(H78="No Sale Record","🔴 Dead - No Sale",IF(H78>90,"🔴 Dead (90+ Days)",IF(H78>60,"🟡 At Risk (61-90 Days)",IF(H78>30,"🟠 Slow (31-60 Days)","🟢 Active (0-30 Days)")))) -> 🔴 Dead (90+ Days) | J78: =IF(N78="NEGATIVE QTY - DATA ERROR",0,D78*E78) -> 6532497.9 | K78: =IF(OR(D78<=0,N78="NEGATIVE QTY - DATA ERROR"),0,CLEANED!J76/D78) -> 0.26442308 | L78: =IF(N78="NEGATIVE QTY - DATA ERROR","Data Error",IF(D78<=CLEANED!N76,"⚠️ Below Reorder Point - Restock Now",IF(AND(H78>90,D78>CLEANED!N76*2),"📦 Overstocked & Dead","✅ Stock Level OK"))) -> 📦 Overstocked & Dead | M78: =CLEANED!P76 -> OK | N78: =CLEANED!Q76 -> OK | O78: =CLEANED!R76 -> OK

Sheet PT1_Category
A3: Category | B3: Cash Tied Up PKR
A4: Clothing | B4: 36854280
A5: 🔴 Dead (90+ Days) | B5: 23450114
A6: 🟠 Slow (31-60 Days) | B6: 5812227.4
A7: 🟡 At Risk (61-90 Days) | B7: 5223792.6
A8: 🟢 Active (0-30 Days) | B8: 2368146.6
A9: Electronics | B9: 38841669
A10: 🔴 Dead - No Sale | B10: 8500770.9
A11: 🔴 Dead (90+ Days) | B11: 2546480.7
A12: 🟠 Slow (31-60 Days) | B12: 16508408
A13: 🟡 At Risk (61-90 Days) | B13: 6086066.1
A14: 🟢 Active (0-30 Days) | B14: 5199943.4
A15: Health & Beauty | B15: 35278643
... A31: Grand Total | B31: 205452105

Sheet PT2_AgingBucket
A3: Aging Bucket | B3: Number of SKUs | C3: Cash Tied Up PKR
A4: 🔴 Dead - No Sale | B4: 4 | C4: 12151600
A5: 🔴 Dead (90+ Days) | B5: 24 | C5: 79522385
A6: 🟠 Slow (31-60 Days) | B6: 22 | C6: 60001397
A7: 🟡 At Risk (61-90 Days) | B7: 13 | C7: 37183522
A8: 🟢 Active (0-30 Days) | B8: 12 | C8: 16593202
A9: Grand Total | B9: 75 | C9: 2.0545211e+08

Sheet  PT3_TopDeadStock
A1: Aging_Bucket | B1: 🔴 Dead (90+ Days)
A3: Product_Name | B3: Cash Tied Up PKR
A4: Chopping Board Set | B4: 9717493.9
A5: Home & Kitchen | B5: 9717493.9
A6: Ankle Weights 2kg | B6: 8535166.6
A7: Sports & Outdoor | B7: 8535166.6
A8: Gym Shorts | B8: 6603560.3
A9: Clothing | B9: 6603560.3
A10: Coffee Maker Drip | B10: 6558410.9
A11: Home & Kitchen | B11: 6558410.9
A12: Summer Dress Floral | B12: 6532497.9
A13: Clothing | B13: 6532497.9
A14: Non-Stick Pan Set 3pc | B14: 5328225
A15: Home & Kitchen | B15: 5328225
... A52: Grand Total | B52: 79522385

Sheet DASHBOARD
A1: INVENTORY HEALTH & DEAD STOCK ANALYSIS
A2: Prepared by: Sundas Memon | Analysis Date: 10-May-2025 | 75 SKUs | 5 Categories | 4 Warehouses
A3: Key Performance Indicators
A4: =SUM(ANALYSIS!J4:J78) -> 2.054521e+08 | F4: =SUMIF(ANALYSIS!I4:I78,"🔴 Dead (90+ Days)",ANALYSIS!J4:J78)+SUMIF(ANALYSIS!I4:I78,"🔴 Dead - No Sale",ANALYSIS!J4:J78) -> 91673984 | K4: =COUNTIF(ANALYSIS!I4:I78,"🔴 Dead (90+ Days)") -> 24 | P4: =(SUMIF(ANALYSIS!I4:I78,"🔴 Dead (90+ Days)",ANALYSIS!J4:J78)+SUMIF(ANALYSIS!I4:I78,"🔴 Dead - No Sale",ANALYSIS!J4:J78))/SUM(ANALYSIS!J4:J78) -> 0.44620611
A9: Total Inventory Value (PKR) | F9: Dead Stock Cash | K9: Dead SKU Count | P9: % Inventory Dead
A29: KEY FINDINGS & RECOMMENDATIONS
A30: FINDING 1 - CRITICAL LIQUIDITY RISK PKR 91.6M representing 44.6% of total inventory value is completely dead, either unsold for 90+ days or with no sale record at all. This includes PKR 79.5M in products dead for 90+ days and PKR 12.1M in products with zero sales history. FINDING 2 - HOME & KITCHEN IS THE BIGGEST PROBLEM Home & Kitchen accounts for PKR 34M in dead stock, making it the single largest problem category in this analysis. With 8 out of 15 SKUs classified as dead stock, this category has a 53% dead stock rate. This pattern points to a systematic issue in purchasing decisions specific to this category and warrants an immediate review of the buying strategy. FINDING 2B - ELECTRONICS HIDDEN RISK Electronics appeared to have only PKR 3M in dead stock. However when No Sale products are included, Electronics dead stock rises to PKR 11.5M, making it the third largest problem category. 3 Electronics SKUs have never recorded a single sale in the system. FINDING 3 - OVERSTOCK CRISIS ON 17 SKUs 17 products are simultaneously classified as dead stock and carrying more than double their required reorder quantity. These represent the highest priority items for immediate action, as the business is holding excessive quantities of products that have completely stopped selling. FINDING 4 - DATA INTEGRITY RISK 2 SKU code conflicts were identified during the audit. SKU-5002 has been assigned to both USB-C Hub and Leather Belt Brown, while SKU-5000 has been assigned to both Smart Plug 4-pack and LED TV 32 inch. Inventory tracking will remain unreliable until unique SKUs are reassigned by the operations team. RECOMMENDATION 1 - IMMEDIATE CLEARANCE SALE Launch a 30-40% discount campaign on the 17 overstocked dead SKUs immediately. Based on current stock valuations, a conservative estimate projects PKR 25-35M in cash recovery within 60 days. Home & Kitchen and Clothing categories should be prioritised first given their disproportionate share of dead stock value. RECOMMENDATION 2 - REVIEW PURCHASING STRATEGY A 32% dead stock rate across all SKUs indicates that buying decisions are not aligned with actual customer demand patterns. It is recommended that a minimum 90-day sales velocity check be implemented as a mandatory step before any new purchase order is approved going forward. RECOMMENDATION 3 - RESOLVE ZERO-SALE PRODUCTS 4 products currently have zero sales history recorded in the system. These should be investigated immediately for supplier return eligibility or inventory write-off. It is possible these products were never properly marketed, or they represent obsolete stock carried forward from a previous period that was never cleared.
A63: Prepared by: Sundas Memon | Tool: Microsoft Excel | Dataset: Synthetic Inventory (75 SKUs) | Analysis Date: 10 May 2025

Sheet CLEANING_LOG
A1: Count: 1136
A3: LOG_ID | B3: Date | C3: Column_Affected | D3: Issue_Found | E3: Action_Taken | F3: Rows_Affected | G3: Why_This_Decision | H3: Status
A4: CL-001 | B4: 45775 | C4: All Columns | D4: 6 completely blank rows found scattered in dataset ; export artifact from CSV | E4: Selected blank rows using Ctrl+G Special → Blanks, deleted entire rows | F4: 6 | G4: Blank rows contain zero data across all 15 columns. No analytical value. Confirmed each row was fully empty before deletion. Not a partial record. | H4: Done
A5: CL-002 | B5: 45775 | C5: All 15 Columns | D5: Columns imported from CSV without correct data types — dates stored as text, numbers as general format | E5: Manually set correct data type for each column: SKU=Text, Quantities=Number, Prices=Number 2dp, Dates=Date YYYY-MM-DD | F5: All Rows | G5: Incorrect data types cause formula errors silently. DATE functions won't work on text-formatted dates. Number formats prevent calculation errors. Must be fixed before any analysis. | H5: Done
A6: CL-003 | B6: 45775 | C6: Last_Sale_Date (Column I) | D6: 1 row found with date in DD/MM/YYYY format instead of standard YYYY-MM-DD. Excel misreads this as text, making stock age calculation return an error for that row. | E6: Used helper formula =IF(ISNUMBER(I2),"OK","TEXT-CHECK") to identify non-date values. Manually corrected 1 row to YYYY-MM-DD format. Deleted helper column after fix. | F6: 1 | G6: All date calculations (DATEDIF, TODAY()-date) require proper date format. A single text-formatted date returns #VALUE error which can cascade through pivot tables. | H6: Done
A7: CL-004 | B7: 45775 | C7: Last_Sale_Date (Column I) | D7: RAW_DATA contained 10 blank Last_Sale_Date rows. After removing BLANK Rows, 4 blank rows remained in CLEANED tab. | E7: Filtered column I for blanks. Filled all 4 remaining blank cells with placeholder date 2020-01-01. Added helper column P (Last_Sale_Date_Flag) using =IF(I2=DATE(2020,1,1),"NO SALE RECORDED","OK") to flag these rows throughout analysis. | F7: 4 | G7: Cannot calculate Days_Since_Last_Sale without a date value. Blank dates would return a #VALUE error breaking the entire aging analysis. Using 2020-01-01 as a placeholder applies a conservative assumption — products with no sale record are treated as extreme dead stock (1,500+ days). This is the safest business assumption because if no sale was ever recorded, the product should be treated as the highest priority dead stock candidate. Assumption is clearly disclosed via helper column P flag throughout the analysis and noted on the dashboard. | H7: Done
A8: CL-005 | B8: 45775 | C8: Quantity_On_Hand (Column F) | D8: 3 rows with negative quantity values found. Physically impossible in real inventory. Likely caused by incorrect return transaction entries. | E8: Added helper column Q (Quantity_Flag). Flagged 3 rows with "NEGATIVE QTY - DATA ERROR". Values NOT changed , changing source data without business confirmation is fabrication. | F8: 3 | G8: These rows require warehouse manager confirmation before correction. Product name, category and cost data still valid. Rows excluded from cash calculation in ANALYSIS tab to avoid false totals. | H8: Flagged | I8: Requires business confirmation
A9: CL-006 | B9: 45775 | C9: Cost_Price_PKR (G), Selling_Price_PKR (H) | D9: 4 rows where Cost_Price_PKR exceeds Selling_Price_PKR. Business is actively selling these products at a financial loss without realising it. | E9: Added helper column R (Margin_Flag). Flagged 4 rows with "SELLING AT LOSS - REVIEW PRICING". Prices NOT changed , prices are factual business data. | F9: 4 | G9: Changing prices would be data fabrication. Correct action is to surface this as a critical business finding on the dashboard. These 4 products are actively losing money on every sale. | H9: Flagged
A10: CL-007 | B10: 45775 | C10: SKU (Column A) | D10: 4 rows flagged with duplicate SKU codes. Found 2 pairs: SKU-5002 assigned to both USB-C Hub and Leather Belt Brown. SKU-5000 assigned to both Smart Plug 4-pack and LED TV 32 inch. | E10: Investigated each pair. Confirmed these are SKU assignment errors, different products given same SKU code. No rows deleted as all products are legitimate. Flagged in helper column S for business owner awareness. | F10: 4 | G10: These are not true duplicate records , they are different products with incorrectly shared SKU codes. Deleting any row would remove valid inventory data. Business owner must reassign correct unique SKUs to these 4 products. This is a system/process finding, not a data cleaning deletion. | H10: Flagged | I10: SKU reassignment required by business
A11: CL-008 | B11: 45775 | C11: Product_Name (B), Category (C), Supplier (D) | D11: Potential leading and trailing spaces in text columns , invisible but silently breaks COUNTIF and pivot table grouping | E11: Applied TRIM() formula to Product_Name, Category and Supplier using temporary column T. Pasted back as values only. Deleted temp column after each. | F11: All Rows - 75 | G11: TRIM is non-destructive and only removes invisible whitespace. Standard practice on every text column before building pivot tables. A single extra space creates duplicate category groups in pivots without any visible warning. | H11: Done
A12: CL-009 | B12: 45775 | C12: Category (Column C) | D12: Possible inconsistent text casing in Category column , mixed case creates duplicate groups in pivot tables | E12: Applied PROPER() formula using temporary column T. Pasted back as values only. Deleted temp column. Verified exactly 5 clean category names in filter dropdown | F12: All Rows - 75 | G12: Pivot tables are case sensitive. Even one inconsistent category name creates a duplicate group , breaking all category level cash totals and dead stock calculations silently. | H12: Done
A13: SUMMARY | B13: 45775 | C13: Full Dataset - All 19 Columns | D13: 9 issue types identified across RAW_DATA. Issues included blank rows, wrong data types, incorrect date formats, blank dates, negative quantities, margin errors, duplicate SKUs, extra spaces and inconsistent casing. | E13: 6 blank rows deleted. All 15 columns formatted correctly. 1 wrong date format corrected. 4 blank dates filled with 2020-01-01 placeholder. 3 negative quantities flagged. 4 margin errors flagged as critical business finding. Duplicate SKUs flagged for business review. TRIM applied to text columns. PROPER applied to Category column. | F13: Final cleaned dataset: 75 rows, 19 columns (A to S) | G13: Conservative approach throughout ,no data fabricated. All business findings surfaced as flags rather than silent deletions. Full audit trail maintained in rows CL-001 through CL-006. | H13: Cleaning Complete

Sheet CHART_DATA
A2: Aging Bucket | B2: Cash Value PKR | E2: Category | F2: Dead Stock Cash PKR
A3: Active (0-30) days | B3: =SUMIF(ANALYSIS!I4:I78,"🟢 Active (0-30 Days)",ANALYSIS!J4:J78) -> 16593202 | E3: Home & Kitchen | F3: =SUMIFS(ANALYSIS!J4:J78,ANALYSIS!C4:C78,"Home & Kitchen",ANALYSIS!I4:I78,"🔴 Dead (90+ Days)") -> 34149865
A4: Slow (31-60 Days) | B4: =SUMIF(ANALYSIS!I4:I78,"🟠 Slow (31-60 Days)",ANALYSIS!J4:J78) -> 60001397 | E4: Clothing | F4: =SUMIFS(ANALYSIS!J4:J78,ANALYSIS!C4:C78,"Clothing",ANALYSIS!I4:I78,"🔴 Dead (90+ Days)")+SUMIFS(ANALYSIS!J4:J78,ANALYSIS!C4:C78,"Clothing",ANALYSIS!I4:I78,"🔴 Dead - No Sale") -> 23450114
A5: At Risk (61-90 Days) | B5: =SUMIF(ANALYSIS!I4:I78,"🟡 At Risk (61-90 Days)",ANALYSIS!J4:J78) -> 37183522 | E5: Sports & Outdoor | F5: =SUMIFS(ANALYSIS!J4:J78,ANALYSIS!C4:C78,"Sports & Outdoor",ANALYSIS!I4:I78,"🔴 Dead (90+ Days)") -> 18155193
A6: Dead (90+ Days) | B6: =SUMIF(ANALYSIS!I4:I78,"🔴 Dead (90+ Days)",ANALYSIS!J4:J78) -> 79522385 | E6: Electronics | F6: =SUMIFS(ANALYSIS!J4:J78,ANALYSIS!C4:C78,"Electronics",ANALYSIS!I4:I78,"🔴 Dead (90+ Days)")+SUMIFS(ANALYSIS!J4:J78,ANALYSIS!C4:C78,"Electronics",ANALYSIS!I4:I78,"🔴 Dead - No Sale") -> 11047252
A7: Dead - No Sale | B7: =SUMIF(ANALYSIS!I4:I78,"🔴 Dead - No Sale",ANALYSIS!J4:J78) -> 12151600 | E7: Health & Beauty | F7: =SUMIFS(ANALYSIS!J4:J78,ANALYSIS!C4:C78,"Health & Beauty",ANALYSIS!I4:I78,"🔴 Dead (90+ Days)")+SUMIFS(ANALYSIS!J4:J78,ANALYSIS!C4:C78,"Health & Beauty",ANALYSIS!I4:I78,"🔴 Dead - No Sale") -> 4871560.1
